Workbook

Sheet 0.요약
A1: AP 대전 튜브라인 — 계획 vs 실적 GAP 및 귀책 판정 요약
A2: 전 항목 자동 계산. 입력은 [1.기준정보] · [2.일별대조] · [4.포장재결품이력]에서만 하십시오.
A4: ① 주차별 계획 vs 실적
A5: 주차 | B5: 기준CAPA 합(개) | C5: 도급 일계획 합(개) | D5: 실적 합(개) | E5: GAP (CAPA-실적) | F5: 계획대비 달성률 | G5: CAPA대비 달성률
A6: 34주 (8/17~8/22) | B6: =SUMIFS('2.일별대조'!$G$4:$G$87,'2.일별대조'!$B$4:$B$87,34) | C6: =SUMIFS('2.일별대조'!$H$4:$H$87,'2.일별대조'!$B$4:$B$87,34) | D6: =SUMIFS('2.일별대조'!$I$4:$I$87,'2.일별대조'!$B$4:$B$87,34) | E6: =$B6-$D6 | F6: =IF($C6=0,0,$D6/$C6) | G6: =IF($B6=0,0,$D6/$B6)
A7: 35주 (8/24~8/29) ← 당주 | B7: =SUMIFS('2.일별대조'!$G$4:$G$87,'2.일별대조'!$B$4:$B$87,35) | C7: =SUMIFS('2.일별대조'!$H$4:$H$87,'2.일별대조'!$B$4:$B$87,35) | D7: =SUMIFS('2.일별대조'!$I$4:$I$87,'2.일별대조'!$B$4:$B$87,35) | E7: =$B7-$D7 | F7: =IF($C7=0,0,$D7/$C7) | G7: =IF($B7=0,0,$D7/$B7)
A8: 2주 합계 | B8: =SUM(B6:B7) | C8: =SUM(C6:C7) | D8: =SUM(D6:D7) | E8: =SUM(E6:E7) | F8: =IF($C8=0,0,$D8/$C8) | G8: =IF($B8=0,0,$D8/$B8)
A11: ② AP 제시 기준 대비 (핵심 논점)
A12: 구분 | B12: 수량(개) | C12: 산출근거
A13: AP 제시 주간 목표 | B13: ='1.기준정보'!$B$7 | C13: 김상은 2026-08-27 통화
A14: AP 제시 보수 기준 | B14: ='1.기준정보'!$B$8 | C14: 동일
A15: 실적 (주 평균) | B15: =IF(COUNT(D6:D7)=0,0,AVERAGE(D6:D7)) | C15: [2.일별대조] 실적 주평균
A16: GAP vs AP 목표 | B16: ='1.기준정보'!$B$7-B15 | C16: AP가 문제 삼는 수량
A17: GAP vs AP 보수기준 | B17: ='1.기준정보'!$B$8-B15 | C17: 최소한 방어해야 할 수량
A19: ③ 귀책별 LOSS 및 시나리오 판정
A20: 구분 | B20: LOSS공수(M·H) | C20: LOSS금액(원) | D20: 구성비
A21: 원청 | B21: ='3.사유별집계'!$C$22 | C21: ='3.사유별집계'!$D$22 | D21: =IF($B$25=0,0,$B21/$B$25)
A22: 도급 | B22: ='3.사유별집계'!$C$23 | C22: ='3.사유별집계'!$D$23 | D22: =IF($B$25=0,0,$B22/$B$25)
A23: 공통 | B23: ='3.사유별집계'!$C$24 | C23: ='3.사유별집계'!$D$24 | D23: =IF($B$25=0,0,$B23/$B$25)
A24: 미정 | B24: ='3.사유별집계'!$C$25 | C24: ='3.사유별집계'!$D$25 | D24: =IF($B$25=0,0,$B24/$B$25)
A25: 합계 | B25: =SUM(B21:B24) | C25: =SUM(C21:C24)
A27: 시나리오 판정 | B27: =IF($B$25=0,"데이터 미입력 — 2.일별대조 시트 입력 필요",IF($B$21/$B$25>=0.6,"A. 원청(포장재) 귀책 우세 → 정산 청구 근거 확보. AP 회신 시 결품 이력 첨부",IF($B$22/$B$25>=0.4,"C. 도급 귀책 우세 → 방어 불가. 즉시 잔업·교대 복원 계획 제출","B. 혼재 → 공통 LOSS 사유별 재분류 후 재판정")))
A29: ④ 36주(8/31~) 대응 체크리스트
A30: No | B30: 항목 | C30: 위치 / 비고 | D30: 담당 | E30: 기한 | F30: 완료
A31: 1 | B31: 튜브 8/17~8/29 일자·호기별 실제 근무형태 확정 | C31: [2.일별대조] E·F열
A32: 2 | B32: 포장재 결품 시간 단위 증빙 확보 | C32: [4.포장재결품이력] — 미작성 시 원청 귀책 주장 불가
A33: 3 | B33: 호기별 실측 UPH 입력 (임시값 350 교체) | C33: [1.기준정보] B22:B28
A34: 4 | B34: AP 제시 캐파의 일/주 단위 확정 | C34: [1.기준정보] ④ 블록 — 회신 전 최우선
A35: 5 | B35: 신 차장 1도급 일계획 수립 로직 확인 | C35: 오더 기준 / 자재 기준 / 인원 기준 중 무엇인가
A36: 6 | B36: AP 회신 2개 항목 확정 (가능 근무형태 + 주간 물량) | C36: [5.AP회신_시뮬]
A37: 7 | B37: 염모동·HMB동 동일 패턴 스크리닝 | C37: 튜브 방어 후 타 동에서 재발 시 프레임 확대
A38: 8 | B38: 36주 일 단위 보고 양식 가동 | C38: AP 예고 사항 — 사후 작성 불가

Sheet 1.기준정보
A1: 튜브라인 기준정보 · 캐파 · 귀책 매핑
A2: 노란 셀 = 반드시 실측값으로 교체 / 파란 글씨 = 하드코딩 입력값 / 검정 = 수식
A4: ① 기준 단가 및 목표
A5: 임률 (원/M·H) | B5: 35121 | C5: AP 대전 BY26 기준. BY27 확정 시 갱신
A6: 주간 가동일수 (일) | B6: 6 | C6: 월~토(특근 포함) 가정. 실제 편성으로 교체
A7: AP 제시 주간 목표수량 (개) | B7: 230000 | C7: 김상은(AP 생산지원팀) 2026-08-27 통화 제시값
A8: AP 제시 보수 기준수량 (개) | B8: 200000 | C8: 동일 통화. OP 휴가 등 감안한 보수 기준
A11: ② 근무형태별 순가동시간 (호기 1대 기준)
A12: 근무형태 | B12: 순가동시간(H) | C12: 비고
A13: 미가동 | B13: 0 | C13: 정지
A14: 1교대 | B14: 8 | C14: 주간 1교대 정상근무
A15: 1교대+잔업 | B15: 10.5 | C15: 잔업 2.5H 가정 — 실제 편성으로 교체
A16: 주간2교대 | B16: 16 | C16: 2교대 8H×2
A17: 주간2교대+잔업 | B17: 19 | C17: 2교대 + 잔업 3H 가정
A18: 특근 | B18: 8 | C18: 토요 특근 1교대
A20: ③ 호기별 UPH 및 근무형태별 일 CAPA (개/일) ※ CAPA = UPH × 순가동시간
A21: 호기 | B21: UPH(개/H) | C21: 미가동 | D21: 1교대 | E21: 1교대+잔업 | F21: 주간2교대 | G21: 주간2교대+잔업 | H21: 특근
A22: 2호기 | B22: 350 | C22: =ROUND($B22*INDEX($B$13:$B$18,MATCH(C$21,$A$13:$A$18,0)),0) | D22: =ROUND($B22*INDEX($B$13:$B$18,MATCH(D$21,$A$13:$A$18,0)),0) | E22: =ROUND($B22*INDEX($B$13:$B$18,MATCH(E$21,$A$13:$A$18,0)),0) | F22: =ROUND($B22*INDEX($B$13:$B$18,MATCH(F$21,$A$13:$A$18,0)),0) | G22: =ROUND($B22*INDEX($B$13:$B$18,MATCH(G$21,$A$13:$A$18,0)),0) | H22: =ROUND($B22*INDEX($B$13:$B$18,MATCH(H$21,$A$13:$A$18,0)),0)
A23: 3호기 | B23: 350 | C23: =ROUND($B23*INDEX($B$13:$B$18,MATCH(C$21,$A$13:$A$18,0)),0) | D23: =ROUND($B23*INDEX($B$13:$B$18,MATCH(D$21,$A$13:$A$18,0)),0) | E23: =ROUND($B23*INDEX($B$13:$B$18,MATCH(E$21,$A$13:$A$18,0)),0) | F23: =ROUND($B23*INDEX($B$13:$B$18,MATCH(F$21,$A$13:$A$18,0)),0) | G23: =ROUND($B23*INDEX($B$13:$B$18,MATCH(G$21,$A$13:$A$18,0)),0) | H23: =ROUND($B23*INDEX($B$13:$B$18,MATCH(H$21,$A$13:$A$18,0)),0)
A24: 4호기 | B24: 350 | C24: =ROUND($B24*INDEX($B$13:$B$18,MATCH(C$21,$A$13:$A$18,0)),0) | D24: =ROUND($B24*INDEX($B$13:$B$18,MATCH(D$21,$A$13:$A$18,0)),0) | E24: =ROUND($B24*INDEX($B$13:$B$18,MATCH(E$21,$A$13:$A$18,0)),0) | F24: =ROUND($B24*INDEX($B$13:$B$18,MATCH(F$21,$A$13:$A$18,0)),0) | G24: =ROUND($B24*INDEX($B$13:$B$18,MATCH(G$21,$A$13:$A$18,0)),0) | H24: =ROUND($B24*INDEX($B$13:$B$18,MATCH(H$21,$A$13:$A$18,0)),0)
A25: 5호기 | B25: 350 | C25: =ROUND($B25*INDEX($B$13:$B$18,MATCH(C$21,$A$13:$A$18,0)),0) | D25: =ROUND($B25*INDEX($B$13:$B$18,MATCH(D$21,$A$13:$A$18,0)),0) | E25: =ROUND($B25*INDEX($B$13:$B$18,MATCH(E$21,$A$13:$A$18,0)),0) | F25: =ROUND($B25*INDEX($B$13:$B$18,MATCH(F$21,$A$13:$A$18,0)),0) | G25: =ROUND($B25*INDEX($B$13:$B$18,MATCH(G$21,$A$13:$A$18,0)),0) | H25: =ROUND($B25*INDEX($B$13:$B$18,MATCH(H$21,$A$13:$A$18,0)),0)
A26: 6호기 | B26: 350 | C26: =ROUND($B26*INDEX($B$13:$B$18,MATCH(C$21,$A$13:$A$18,0)),0) | D26: =ROUND($B26*INDEX($B$13:$B$18,MATCH(D$21,$A$13:$A$18,0)),0) | E26: =ROUND($B26*INDEX($B$13:$B$18,MATCH(E$21,$A$13:$A$18,0)),0) | F26: =ROUND($B26*INDEX($B$13:$B$18,MATCH(F$21,$A$13:$A$18,0)),0) | G26: =ROUND($B26*INDEX($B$13:$B$18,MATCH(G$21,$A$13:$A$18,0)),0) | H26: =ROUND($B26*INDEX($B$13:$B$18,MATCH(H$21,$A$13:$A$18,0)),0)
A27: 7호기 | B27: 350 | C27: =ROUND($B27*INDEX($B$13:$B$18,MATCH(C$21,$A$13:$A$18,0)),0) | D27: =ROUND($B27*INDEX($B$13:$B$18,MATCH(D$21,$A$13:$A$18,0)),0) | E27: =ROUND($B27*INDEX($B$13:$B$18,MATCH(E$21,$A$13:$A$18,0)),0) | F27: =ROUND($B27*INDEX($B$13:$B$18,MATCH(F$21,$A$13:$A$18,0)),0) | G27: =ROUND($B27*INDEX($B$13:$B$18,MATCH(G$21,$A$13:$A$18,0)),0) | H27: =ROUND($B27*INDEX($B$13:$B$18,MATCH(H$21,$A$13:$A$18,0)),0)
A28: 8호기 | B28: 350 | C28: =ROUND($B28*INDEX($B$13:$B$18,MATCH(C$21,$A$13:$A$18,0)),0) | D28: =ROUND($B28*INDEX($B$13:$B$18,MATCH(D$21,$A$13:$A$18,0)),0) | E28: =ROUND($B28*INDEX($B$13:$B$18,MATCH(E$21,$A$13:$A$18,0)),0) | F28: =ROUND($B28*INDEX($B$13:$B$18,MATCH(F$21,$A$13:$A$18,0)),0) | G28: =ROUND($B28*INDEX($B$13:$B$18,MATCH(G$21,$A$13:$A$18,0)),0) | H28: =ROUND($B28*INDEX($B$13:$B$18,MATCH(H$21,$A$13:$A$18,0)),0)
A29: ※ UPH 350개/H = 임시 자리값. MES 실측 UPH로 교체 필수. 교체 전 산출된 CAPA·GAP·LOSS 금액은 무효.
A31: ④ AP 제시 캐파 기준 (2026-08-27 통화 원문 — 검증 대상, 우리 산식과 별도)
A32: 구분 | B32: AP 제시 수량(개) | C32: 단위(일/주) 확인 | D32: 비고
A33: 4·5·6호기 주간2교대 | B33: 40000 | C33: 미확정 | D33: '4만개보다 조금 더 가능하나 4만으로 계산' (원문)
A34: 2·3호기 잔업 | B34: 30000 | C34: 미확정 | D34: 원문
A35: 7·8호기 잔업 | B35: 30000 | C35: 미확정 | D35: 8호기 가동 편차 감안 시 20,000으로 보수 적용
A36: 7·8호기 잔업(보수) | B36: 20000 | C36: 미확정 | D36: 원문 보수값
A37: AP 결론: 도급 일계획 반영 필요 수량 | B37: 230000 | C37: 주간 누계로 추정 | D37: OP 휴가로 2교대 1개 해제 시에도 잔업 대응하면 1만개 차이
A38: AP 결론: 보수 기준 | B38: 200000 | C38: 주간 누계로 추정 | D38: '1주 20만개 기준으로 가능한지 현장과 확인 요청'
A40: ※ 개별 라인 합(4만+3만+2만=9만)과 결론값(23만)의 단위가 통화상 일치하지 않음. 일/주 단위 확정이 AP 회신 전 최우선 확인사항.
A42: ⑤ 비가동 사유 → 귀책 매핑 (공통 LOSS 일괄 50:50 금지 — 사유별 귀책 확정)
A43: 비가동 사유 | B43: 귀책 | C43: 판정 기준 / 증빙
A44: 포장재 미입고 | B44: 원청 | C44: 자재 결품 시각~입고 시각 로그. [4.포장재결품이력] 시트 증빙 필수
A45: 원료·부자재 미입고 | B45: 원청 | C45: 입고확인 파렛 기록
A46: 오더 미확정·계획변경 | B46: 원청 | C46: AP 계획 변경 통보 이력
A47: 품목 교체(換替) | B47: 공통 | C47: 표준 교체시간 초과분만 도급 귀책
...

Sheet 2.일별대조
A1: 일자·호기별 계획 / 실적 / 비가동 3단 대조
A2: 노란 셀만 입력. 회색 수식열은 건드리지 마십시오. 3행 = 예시행(실제 데이터로 덮어쓰기).
A3: 일자 | B3: 주차 | C3: 요일 | D3: 호기 | E3: AP계획 근무형태 | F3: 실제 근무형태 | G3: 기준CAPA (AP계획형태) | H3: 도급 일계획 (개) | I3: 실적 (개) | J3: CAPA대비 달성률 | K3: 투입인원 (명) | L3: 가동시간 (H) | M3: 비가동시간 (H) | N3: 비가동 사유 | O3: 귀책 (자동) | P3: LOSS공수 (M·H) | Q3: LOSS금액 (원) | R3: 비고
A4: 46251 | B4: =IF($A4="","",WEEKNUM($A4,21)) | C4: =IF($A4="","",CHOOSE(WEEKDAY($A4),"일","월","화","수","목","금","토")) | D4: 2호기 | E4: 주간2교대 | F4: 1교대 | G4: =IF(OR($D4="",$E4=""),"",INDEX('1.기준정보'!$C$22:$H$28,MATCH($D4,'1.기준정보'!$A$22:$A$28,0),MATCH($E4,'1.기준정보'!$C$21:$H$21,0))) | H4: 2800 | I4: 2650 | J4: =IF(OR($G4="",$G4=0,$I4=""),"",$I4/$G4) | K4: 12 | L4: 8 | M4: 8 | N4: 포장재 미입고 | O4: =IF($N4="","",IFERROR(INDEX('1.기준정보'!$B$44:$B$55,MATCH($N4,'1.기준정보'!$A$44:$A$55,0)),"미정")) | P4: =IF(OR($M4="",$K4=""),"",$M4*$K4) | Q4: =IF($P4="","",$P4*'1.기준정보'!$B$5) | R4: ◀ 예시행 — 실제 데이터로 덮어쓰기
A5: 46251 | B5: =IF($A5="","",WEEKNUM($A5,21)) | C5: =IF($A5="","",CHOOSE(WEEKDAY($A5),"일","월","화","수","목","금","토")) | D5: 3호기 | G5: =IF(OR($D5="",$E5=""),"",INDEX('1.기준정보'!$C$22:$H$28,MATCH($D5,'1.기준정보'!$A$22:$A$28,0),MATCH($E5,'1.기준정보'!$C$21:$H$21,0))) | J5: =IF(OR($G5="",$G5=0,$I5=""),"",$I5/$G5) | O5: =IF($N5="","",IFERROR(INDEX('1.기준정보'!$B$44:$B$55,MATCH($N5,'1.기준정보'!$A$44:$A$55,0)),"미정")) | P5: =IF(OR($M5="",$K5=""),"",$M5*$K5) | Q5: =IF($P5="","",$P5*'1.기준정보'!$B$5)
A6: 46251 | B6: =IF($A6="","",WEEKNUM($A6,21)) | C6: =IF($A6="","",CHOOSE(WEEKDAY($A6),"일","월","화","수","목","금","토")) | D6: 4호기 | G6: =IF(OR($D6="",$E6=""),"",INDEX('1.기준정보'!$C$22:$H$28,MATCH($D6,'1.기준정보'!$A$22:$A$28,0),MATCH($E6,'1.기준정보'!$C$21:$H$21,0))) | J6: =IF(OR($G6="",$G6=0,$I6=""),"",$I6/$G6) | O6: =IF($N6="","",IFERROR(INDEX('1.기준정보'!$B$44:$B$55,MATCH($N6,'1.기준정보'!$A$44:$A$55,0)),"미정")) | P6: =IF(OR($M6="",$K6=""),"",$M6*$K6) | Q6: =IF($P6="","",$P6*'1.기준정보'!$B$5)
A7: 46251 | B7: =IF($A7="","",WEEKNUM($A7,21)) | C7: =IF($A7="","",CHOOSE(WEEKDAY($A7),"일","월","화","수","목","금","토")) | D7: 5호기 | G7: =IF(OR($D7="",$E7=""),"",INDEX('1.기준정보'!$C$22:$H$28,MATCH($D7,'1.기준정보'!$A$22:$A$28,0),MATCH($E7,'1.기준정보'!$C$21:$H$21,0))) | J7: =IF(OR($G7="",$G7=0,$I7=""),"",$I7/$G7) | O7: =IF($N7="","",IFERROR(INDEX('1.기준정보'!$B$44:$B$55,MATCH($N7,'1.기준정보'!$A$44:$A$55,0)),"미정")) | P7: =IF(OR($M7="",$K7=""),"",$M7*$K7) | Q7: =IF($P7="","",$P7*'1.기준정보'!$B$5)
A8: 46251 | B8: =IF($A8="","",WEEKNUM($A8,21)) | C8: =IF($A8="","",CHOOSE(WEEKDAY($A8),"일","월","화","수","목","금","토")) | D8: 6호기 | G8: =IF(OR($D8="",$E8=""),"",INDEX('1.기준정보'!$C$22:$H$28,MATCH($D8,'1.기준정보'!$A$22:$A$28,0),MATCH($E8,'1.기준정보'!$C$21:$H$21,0))) | J8: =IF(OR($G8="",$G8=0,$I8=""),"",$I8/$G8) | O8: =IF($N8="","",IFERROR(INDEX('1.기준정보'!$B$44:$B$55,MATCH($N8,'1.기준정보'!$A$44:$A$55,0)),"미정")) | P8: =IF(OR($M8="",$K8=""),"",$M8*$K8) | Q8: =IF($P8="","",$P8*'1.기준정보'!$B$5)
A9: 46251 | B9: =IF($A9="","",WEEKNUM($A9,21)) | C9: =IF($A9="","",CHOOSE(WEEKDAY($A9),"일","월","화","수","목","금","토")) | D9: 7호기 | G9: =IF(OR($D9="",$E9=""),"",INDEX('1.기준정보'!$C$22:$H$28,MATCH($D9,'1.기준정보'!$A$22:$A$28,0),MATCH($E9,'1.기준정보'!$C$21:$H$21,0))) | J9: =IF(OR($G9="",$G9=0,$I9=""),"",$I9/$G9) | O9: =IF($N9="","",IFERROR(INDEX('1.기준정보'!$B$44:$B$55,MATCH($N9,'1.기준정보'!$A$44:$A$55,0)),"미정")) | P9: =IF(OR($M9="",$K9=""),"",$M9*$K9) | Q9: =IF($P9="","",$P9*'1.기준정보'!$B$5)
A10: 46251 | B10: =IF($A10="","",WEEKNUM($A10,21)) | C10: =IF($A10="","",CHOOSE(WEEKDAY($A10),"일","월","화","수","목","금","토")) | D10: 8호기 | G10: =IF(OR($D10="",$E10=""),"",INDEX('1.기준정보'!$C$22:$H$28,MATCH($D10,'1.기준정보'!$A$22:$A$28,0),MATCH($E10,'1.기준정보'!$C$21:$H$21,0))) | J10: =IF(OR($G10="",$G10=0,$I10=""),"",$I10/$G10) | O10: =IF($N10="","",IFERROR(INDEX('1.기준정보'!$B$44:$B$55,MATCH($N10,'1.기준정보'!$A$44:$A$55,0)),"미정")) | P10: =IF(OR($M10="",$K10=""),"",$M10*$K10) | Q10: =IF($P10="","",$P10*'1.기준정보'!$B$5)
A11: 46252 | B11: =IF($A11="","",WEEKNUM($A11,21)) | C11: =IF($A11="","",CHOOSE(WEEKDAY($A11),"일","월","화","수","목","금","토")) | D11: 2호기 | G11: =IF(OR($D11="",$E11=""),"",INDEX('1.기준정보'!$C$22:$H$28,MATCH($D11,'1.기준정보'!$A$22:$A$28,0),MATCH($E11,'1.기준정보'!$C$21:$H$21,0))) | J11: =IF(OR($G11="",$G11=0,$I11=""),"",$I11/$G11) | O11: =IF($N11="","",IFERROR(INDEX('1.기준정보'!$B$44:$B$55,MATCH($N11,'1.기준정보'!$A$44:$A$55,0)),"미정")) | P11: =IF(OR($M11="",$K11=""),"",$M11*$K11) | Q11: =IF($P11="","",$P11*'1.기준정보'!$B$5)
A12: 46252 | B12: =IF($A12="","",WEEKNUM($A12,21)) | C12: =IF($A12="","",CHOOSE(WEEKDAY($A12),"일","월","화","수","목","금","토")) | D12: 3호기 | G12: =IF(OR($D12="",$E12=""),"",INDEX('1.기준정보'!$C$22:$H$28,MATCH($D12,'1.기준정보'!$A$22:$A$28,0),MATCH($E12,'1.기준정보'!$C$21:$H$21,0))) | J12: =IF(OR($G12="",$G12=0,$I12=""),"",$I12/$G12) | O12: =IF($N12="","",IFERROR(INDEX('1.기준정보'!$B$44:$B$55,MATCH($N12,'1.기준정보'!$A$44:$A$55,0)),"미정")) | P12: =IF(OR($M12="",$K12=""),"",$M12*$K12) | Q12: =IF($P12="","",$P12*'1.기준정보'!$B$5)
A13: 46252 | B13: =IF($A13="","",WEEKNUM($A13,21)) | C13: =IF($A13="","",CHOOSE(WEEKDAY($A13),"일","월","화","수","목","금","토")) | D13: 4호기 | G13: =IF(OR($D13="",$E13=""),"",INDEX('1.기준정보'!$C$22:$H$28,MATCH($D13,'1.기준정보'!$A$22:$A$28,0),MATCH($E13,'1.기준정보'!$C$21:$H$21,0))) | J13: =IF(OR($G13="",$G13=0,$I13=""),"",$I13/$G13) | O13: =IF($N13="","",IFERROR(INDEX('1.기준정보'!$B$44:$B$55,MATCH($N13,'1.기준정보'!$A$44:$A$55,0)),"미정")) | P13: =IF(OR($M13="",$K13=""),"",$M13*$K13) | Q13: =IF($P13="","",$P13*'1.기준정보'!$B$5)
A14: 46252 | B14: =IF($A14="","",WEEKNUM($A14,21)) | C14: =IF($A14="","",CHOOSE(WEEKDAY($A14),"일","월","화","수","목","금","토")) | D14: 5호기 | G14: =IF(OR($D14="",$E14=""),"",INDEX('1.기준정보'!$C$22:$H$28,MATCH($D14,'1.기준정보'!$A$22:$A$28,0),MATCH($E14,'1.기준정보'!$C$21:$H$21,0))) | J14: =IF(OR($G14="",$G14=0,$I14=""),"",$I14/$G14) | O14: =IF($N14="","",IFERROR(INDEX('1.기준정보'!$B$44:$B$55,MATCH($N14,'1.기준정보'!$A$44:$A$55,0)),"미정")) | P14: =IF(OR($M14="",$K14=""),"",$M14*$K14) | Q14: =IF($P14="","",$P14*'1.기준정보'!$B$5)
A15: 46252 | B15: =IF($A15="","",WEEKNUM($A15,21)) | C15: =IF($A15="","",CHOOSE(WEEKDAY($A15),"일","월","화","수","목","금","토")) | D15: 6호기 | G15: =IF(OR($D15="",$E15=""),"",INDEX('1.기준정보'!$C$22:$H$28,MATCH($D15,'1.기준정보'!$A$22:$A$28,0),MATCH($E15,'1.기준정보'!$C$21:$H$21,0))) | J15: =IF(OR($G15="",$G15=0,$I15=""),"",$I15/$G15) | O15: =IF($N15="","",IFERROR(INDEX('1.기준정보'!$B$44:$B$55,MATCH($N15,'1.기준정보'!$A$44:$A$55,0)),"미정")) | P15: =IF(OR($M15="",$K15=""),"",$M15*$K15) | Q15: =IF($P15="","",$P15*'1.기준정보'!$B$5)
A16: 46252 | B16: =IF($A16="","",WEEKNUM($A16,21)) | C16: =IF($A16="","",CHOOSE(WEEKDAY($A16),"일","월","화","수","목","금","토")) | D16: 7호기 | G16: =IF(OR($D16="",$E16=""),"",INDEX('1.기준정보'!$C$22:$H$28,MATCH($D16,'1.기준정보'!$A$22:$A$28,0),MATCH($E16,'1.기준정보'!$C$21:$H$21,0))) | J16: =IF(OR($G16="",$G16=0,$I16=""),"",$I16/$G16) | O16: =IF($N16="","",IFERROR(INDEX('1.기준정보'!$B$44:$B$55,MATCH($N16,'1.기준정보'!$A$44:$A$55,0)),"미정")) | P16: =IF(OR($M16="",$K16=""),"",$M16*$K16) | Q16: =IF($P16="","",$P16*'1.기준정보'!$B$5)
... A87: 46263 | B87: =IF($A87="","",WEEKNUM($A87,21)) | C87: =IF($A87="","",CHOOSE(WEEKDAY($A87),"일","월","화","수","목","금","토")) | D87: 8호기 | G87: =IF(OR($D87="",$E87=""),"",INDEX('1.기준정보'!$C$22:$H$28,MATCH($D87,'1.기준정보'!$A$22:$A$28,0),MATCH($E87,'1.기준정보'!$C$21:$H$21,0))) | J87: =IF(OR($G87="",$G87=0,$I87=""),"",$I87/$G87) | O87: =IF($N87="","",IFERROR(INDEX('1.기준정보'!$B$44:$B$55,MATCH($N87,'1.기준정보'!$A$44:$A$55,0)),"미정")) | P87: =IF(OR($M87="",$K87=""),"",$M87*$K87) | Q87: =IF($P87="","",$P87*'1.기준정보'!$B$5)
A89: 합계 | G89: =SUM(G4:G87) | H89: =SUM(H4:H87) | I89: =SUM(I4:I87) | M89: =SUM(M4:M87) | P89: =SUM(P4:P87) | Q89: =SUM(Q4:Q87)

Sheet 3.사유별집계
A1: 비가동 사유별 · 귀책별 LOSS 집계
A2: 전 항목 자동 계산. [2.일별대조] 입력에 연동됩니다.
A4: ① 사유별 집계
A5: 비가동 사유 | B5: 귀책 | C5: 비가동시간(H) | D5: LOSS공수(M·H) | E5: LOSS금액(원) | F5: 건수 | G5: 구성비(공수)
A6: ='1.기준정보'!$A$44 | B6: ='1.기준정보'!$B$44 | C6: =SUMIFS('2.일별대조'!$M$4:$M$87,'2.일별대조'!$N$4:$N$87,$A6) | D6: =SUMIFS('2.일별대조'!$P$4:$P$87,'2.일별대조'!$N$4:$N$87,$A6) | E6: =SUMIFS('2.일별대조'!$Q$4:$Q$87,'2.일별대조'!$N$4:$N$87,$A6) | F6: =COUNTIFS('2.일별대조'!$N$4:$N$87,$A6) | G6: =IF($D$18=0,0,$D6/$D$18)
A7: ='1.기준정보'!$A$45 | B7: ='1.기준정보'!$B$45 | C7: =SUMIFS('2.일별대조'!$M$4:$M$87,'2.일별대조'!$N$4:$N$87,$A7) | D7: =SUMIFS('2.일별대조'!$P$4:$P$87,'2.일별대조'!$N$4:$N$87,$A7) | E7: =SUMIFS('2.일별대조'!$Q$4:$Q$87,'2.일별대조'!$N$4:$N$87,$A7) | F7: =COUNTIFS('2.일별대조'!$N$4:$N$87,$A7) | G7: =IF($D$18=0,0,$D7/$D$18)
A8: ='1.기준정보'!$A$46 | B8: ='1.기준정보'!$B$46 | C8: =SUMIFS('2.일별대조'!$M$4:$M$87,'2.일별대조'!$N$4:$N$87,$A8) | D8: =SUMIFS('2.일별대조'!$P$4:$P$87,'2.일별대조'!$N$4:$N$87,$A8) | E8: =SUMIFS('2.일별대조'!$Q$4:$Q$87,'2.일별대조'!$N$4:$N$87,$A8) | F8: =COUNTIFS('2.일별대조'!$N$4:$N$87,$A8) | G8: =IF($D$18=0,0,$D8/$D$18)
A9: ='1.기준정보'!$A$47 | B9: ='1.기준정보'!$B$47 | C9: =SUMIFS('2.일별대조'!$M$4:$M$87,'2.일별대조'!$N$4:$N$87,$A9) | D9: =SUMIFS('2.일별대조'!$P$4:$P$87,'2.일별대조'!$N$4:$N$87,$A9) | E9: =SUMIFS('2.일별대조'!$Q$4:$Q$87,'2.일별대조'!$N$4:$N$87,$A9) | F9: =COUNTIFS('2.일별대조'!$N$4:$N$87,$A9) | G9: =IF($D$18=0,0,$D9/$D$18)
A10: ='1.기준정보'!$A$48 | B10: ='1.기준정보'!$B$48 | C10: =SUMIFS('2.일별대조'!$M$4:$M$87,'2.일별대조'!$N$4:$N$87,$A10) | D10: =SUMIFS('2.일별대조'!$P$4:$P$87,'2.일별대조'!$N$4:$N$87,$A10) | E10: =SUMIFS('2.일별대조'!$Q$4:$Q$87,'2.일별대조'!$N$4:$N$87,$A10) | F10: =COUNTIFS('2.일별대조'!$N$4:$N$87,$A10) | G10: =IF($D$18=0,0,$D10/$D$18)
A11: ='1.기준정보'!$A$49 | B11: ='1.기준정보'!$B$49 | C11: =SUMIFS('2.일별대조'!$M$4:$M$87,'2.일별대조'!$N$4:$N$87,$A11) | D11: =SUMIFS('2.일별대조'!$P$4:$P$87,'2.일별대조'!$N$4:$N$87,$A11) | E11: =SUMIFS('2.일별대조'!$Q$4:$Q$87,'2.일별대조'!$N$4:$N$87,$A11) | F11: =COUNTIFS('2.일별대조'!$N$4:$N$87,$A11) | G11: =IF($D$18=0,0,$D11/$D$18)
A12: ='1.기준정보'!$A$50 | B12: ='1.기준정보'!$B$50 | C12: =SUMIFS('2.일별대조'!$M$4:$M$87,'2.일별대조'!$N$4:$N$87,$A12) | D12: =SUMIFS('2.일별대조'!$P$4:$P$87,'2.일별대조'!$N$4:$N$87,$A12) | E12: =SUMIFS('2.일별대조'!$Q$4:$Q$87,'2.일별대조'!$N$4:$N$87,$A12) | F12: =COUNTIFS('2.일별대조'!$N$4:$N$87,$A12) | G12: =IF($D$18=0,0,$D12/$D$18)
A13: ='1.기준정보'!$A$51 | B13: ='1.기준정보'!$B$51 | C13: =SUMIFS('2.일별대조'!$M$4:$M$87,'2.일별대조'!$N$4:$N$87,$A13) | D13: =SUMIFS('2.일별대조'!$P$4:$P$87,'2.일별대조'!$N$4:$N$87,$A13) | E13: =SUMIFS('2.일별대조'!$Q$4:$Q$87,'2.일별대조'!$N$4:$N$87,$A13) | F13: =COUNTIFS('2.일별대조'!$N$4:$N$87,$A13) | G13: =IF($D$18=0,0,$D13/$D$18)
A14: ='1.기준정보'!$A$52 | B14: ='1.기준정보'!$B$52 | C14: =SUMIFS('2.일별대조'!$M$4:$M$87,'2.일별대조'!$N$4:$N$87,$A14) | D14: =SUMIFS('2.일별대조'!$P$4:$P$87,'2.일별대조'!$N$4:$N$87,$A14) | E14: =SUMIFS('2.일별대조'!$Q$4:$Q$87,'2.일별대조'!$N$4:$N$87,$A14) | F14: =COUNTIFS('2.일별대조'!$N$4:$N$87,$A14) | G14: =IF($D$18=0,0,$D14/$D$18)
A15: ='1.기준정보'!$A$53 | B15: ='1.기준정보'!$B$53 | C15: =SUMIFS('2.일별대조'!$M$4:$M$87,'2.일별대조'!$N$4:$N$87,$A15) | D15: =SUMIFS('2.일별대조'!$P$4:$P$87,'2.일별대조'!$N$4:$N$87,$A15) | E15: =SUMIFS('2.일별대조'!$Q$4:$Q$87,'2.일별대조'!$N$4:$N$87,$A15) | F15: =COUNTIFS('2.일별대조'!$N$4:$N$87,$A15) | G15: =IF($D$18=0,0,$D15/$D$18)
A16: ='1.기준정보'!$A$54 | B16: ='1.기준정보'!$B$54 | C16: =SUMIFS('2.일별대조'!$M$4:$M$87,'2.일별대조'!$N$4:$N$87,$A16) | D16: =SUMIFS('2.일별대조'!$P$4:$P$87,'2.일별대조'!$N$4:$N$87,$A16) | E16: =SUMIFS('2.일별대조'!$Q$4:$Q$87,'2.일별대조'!$N$4:$N$87,$A16) | F16: =COUNTIFS('2.일별대조'!$N$4:$N$87,$A16) | G16: =IF($D$18=0,0,$D16/$D$18)
A17: ='1.기준정보'!$A$55 | B17: ='1.기준정보'!$B$55 | C17: =SUMIFS('2.일별대조'!$M$4:$M$87,'2.일별대조'!$N$4:$N$87,$A17) | D17: =SUMIFS('2.일별대조'!$P$4:$P$87,'2.일별대조'!$N$4:$N$87,$A17) | E17: =SUMIFS('2.일별대조'!$Q$4:$Q$87,'2.일별대조'!$N$4:$N$87,$A17) | F17: =COUNTIFS('2.일별대조'!$N$4:$N$87,$A17) | G17: =IF($D$18=0,0,$D17/$D$18)
A18: 합계 | C18: =SUM(C6:C17) | D18: =SUM(D6:D17) | E18: =SUM(E6:E17) | F18: =SUM(F6:F17)
A20: ② 귀책별 집계 — 협상·정산 근거
A21: 귀책 | B21: 비가동시간(H) | C21: LOSS공수(M·H) | D21: LOSS금액(원) | E21: 구성비(공수) | F21: 해석
A22: 원청 | B22: =SUMIFS('2.일별대조'!$M$4:$M$87,'2.일별대조'!$O$4:$O$87,$A22) | C22: =SUMIFS('2.일별대조'!$P$4:$P$87,'2.일별대조'!$O$4:$O$87,$A22) | D22: =SUMIFS('2.일별대조'!$Q$4:$Q$87,'2.일별대조'!$O$4:$O$87,$A22) | E22: =IF($C$26=0,0,$C22/$C$26) | F22: AP 귀책 → 정산 청구 가능 (BY26 AP 귀책 LOSS 52% 실적 준용)
A23: 도급 | B23: =SUMIFS('2.일별대조'!$M$4:$M$87,'2.일별대조'!$O$4:$O$87,$A23) | C23: =SUMIFS('2.일별대조'!$P$4:$P$87,'2.일별대조'!$O$4:$O$87,$A23) | D23: =SUMIFS('2.일별대조'!$Q$4:$Q$87,'2.일별대조'!$O$4:$O$87,$A23) | E23: =IF($C$26=0,0,$C23/$C$26) | F23: 제니엘 귀책 → 자체 개선 대상. 협상에서 방어 불가
A24: 공통 | B24: =SUMIFS('2.일별대조'!$M$4:$M$87,'2.일별대조'!$O$4:$O$87,$A24) | C24: =SUMIFS('2.일별대조'!$P$4:$P$87,'2.일별대조'!$O$4:$O$87,$A24) | D24: =SUMIFS('2.일별대조'!$Q$4:$Q$87,'2.일별대조'!$O$4:$O$87,$A24) | E24: =IF($C$26=0,0,$C24/$C$26) | F24: 사유별 재분류 필요. 일괄 50:50 배분 금지
A25: 미정 | B25: =SUMIFS('2.일별대조'!$M$4:$M$87,'2.일별대조'!$O$4:$O$87,$A25) | C25: =SUMIFS('2.일별대조'!$P$4:$P$87,'2.일별대조'!$O$4:$O$87,$A25) | D25: =SUMIFS('2.일별대조'!$Q$4:$Q$87,'2.일별대조'!$O$4:$O$87,$A25) | E25: =IF($C$26=0,0,$C25/$C$26) | F25: 귀책 미확정 → AP 회신 전 반드시 0으로 해소
A26: 합계 | B26: =SUM(B22:B25) | C26: =SUM(C22:C25) | D26: =SUM(D22:D25)

Sheet 4.포장재결품이력
A1: 포장재·부자재 결품 이력 (원청 귀책 LOSS 증빙)
A2: 이 시트가 비면 '포장재 때문'이라는 우리 주장은 성립하지 않습니다. 시(時) 단위로 기록하십시오.
A3: 일자 | B3: 품목코드 | C3: 품목명 | D3: 영향 호기 | E3: 결품 발생시각 | F3: 자재 입고시각 | G3: 라인 재가동시각 | H3: 비가동시간(H) | I3: 투입인원(명) | J3: LOSS공수(M·H) | K3: 미생산 추정수량(개) | L3: 증빙(문서/사진)
A4: 46252 | B4: PKG-TB-0142 | C4: 튜브 단상자 (예시) | D4: 4호기 | E4: 46252.396 | F4: 46252.583 | G4: 46252.604 | H4: =IF(OR($E4="",$G4=""),"",ROUND(($G4-$E4)*24,2)) | I4: 12 | J4: =IF(OR($H4="",$I4=""),"",$H4*$I4) | K4: 1750 | L4: ◀ 예시행 — 실제 데이터로 덮어쓰기
H5: =IF(OR($E5="",$G5=""),"",ROUND(($G5-$E5)*24,2)) | J5: =IF(OR($H5="",$I5=""),"",$H5*$I5)
H6: =IF(OR($E6="",$G6=""),"",ROUND(($G6-$E6)*24,2)) | J6: =IF(OR($H6="",$I6=""),"",$H6*$I6)
H7: =IF(OR($E7="",$G7=""),"",ROUND(($G7-$E7)*24,2)) | J7: =IF(OR($H7="",$I7=""),"",$H7*$I7)
H8: =IF(OR($E8="",$G8=""),"",ROUND(($G8-$E8)*24,2)) | J8: =IF(OR($H8="",$I8=""),"",$H8*$I8)
H9: =IF(OR($E9="",$G9=""),"",ROUND(($G9-$E9)*24,2)) | J9: =IF(OR($H9="",$I9=""),"",$H9*$I9)
H10: =IF(OR($E10="",$G10=""),"",ROUND(($G10-$E10)*24,2)) | J10: =IF(OR($H10="",$I10=""),"",$H10*$I10)
H11: =IF(OR($E11="",$G11=""),"",ROUND(($G11-$E11)*24,2)) | J11: =IF(OR($H11="",$I11=""),"",$H11*$I11)
H12: =IF(OR($E12="",$G12=""),"",ROUND(($G12-$E12)*24,2)) | J12: =IF(OR($H12="",$I12=""),"",$H12*$I12)
H13: =IF(OR($E13="",$G13=""),"",ROUND(($G13-$E13)*24,2)) | J13: =IF(OR($H13="",$I13=""),"",$H13*$I13)
H14: =IF(OR($E14="",$G14=""),"",ROUND(($G14-$E14)*24,2)) | J14: =IF(OR($H14="",$I14=""),"",$H14*$I14)
H15: =IF(OR($E15="",$G15=""),"",ROUND(($G15-$E15)*24,2)) | J15: =IF(OR($H15="",$I15=""),"",$H15*$I15)
H16: =IF(OR($E16="",$G16=""),"",ROUND(($G16-$E16)*24,2)) | J16: =IF(OR($H16="",$I16=""),"",$H16*$I16)
... H63: =IF(OR($E63="",$G63=""),"",ROUND(($G63-$E63)*24,2)) | J63: =IF(OR($H63="",$I63=""),"",$H63*$I63)
A65: 합계 | H65: =SUM(H4:H63) | J65: =SUM(J4:J63) | K65: =SUM(K4:K63) | L65: → [3.사유별집계] '포장재 미입고' 행과 대조하여 일치 여부 확인

Sheet 5.AP회신_시뮬
A1: 근무형태 시나리오별 주간 대응가능 물량 시뮬레이션
A2: AP 요구 회신 2개 항목: ① 제니엘이 가능한 근무형태 ② 그 형태의 주간 물량. 이 시트가 그 답변입니다.
A4: ① 시나리오별 호기 근무형태 설정 (노란 셀에서 선택)
A5: 호기 | B5: A. 현행 근무형태 | C5: A. 일CAPA | D5: B. 잔업복원 근무형태 | E5: B. 일CAPA | F5: C. 풀가동 근무형태 | G5: C. 일CAPA
A6: 2호기 | B6: 1교대 | C6: =IF($B6="","",INDEX('1.기준정보'!$C$22:$H$28,MATCH($A6,'1.기준정보'!$A$22:$A$28,0),MATCH($B6,'1.기준정보'!$C$21:$H$21,0))) | D6: 1교대+잔업 | E6: =IF($D6="","",INDEX('1.기준정보'!$C$22:$H$28,MATCH($A6,'1.기준정보'!$A$22:$A$28,0),MATCH($D6,'1.기준정보'!$C$21:$H$21,0))) | F6: 1교대+잔업 | G6: =IF($F6="","",INDEX('1.기준정보'!$C$22:$H$28,MATCH($A6,'1.기준정보'!$A$22:$A$28,0),MATCH($F6,'1.기준정보'!$C$21:$H$21,0)))
A7: 3호기 | B7: 1교대 | C7: =IF($B7="","",INDEX('1.기준정보'!$C$22:$H$28,MATCH($A7,'1.기준정보'!$A$22:$A$28,0),MATCH($B7,'1.기준정보'!$C$21:$H$21,0))) | D7: 1교대+잔업 | E7: =IF($D7="","",INDEX('1.기준정보'!$C$22:$H$28,MATCH($A7,'1.기준정보'!$A$22:$A$28,0),MATCH($D7,'1.기준정보'!$C$21:$H$21,0))) | F7: 1교대+잔업 | G7: =IF($F7="","",INDEX('1.기준정보'!$C$22:$H$28,MATCH($A7,'1.기준정보'!$A$22:$A$28,0),MATCH($F7,'1.기준정보'!$C$21:$H$21,0)))
A8: 4호기 | B8: 주간2교대 | C8: =IF($B8="","",INDEX('1.기준정보'!$C$22:$H$28,MATCH($A8,'1.기준정보'!$A$22:$A$28,0),MATCH($B8,'1.기준정보'!$C$21:$H$21,0))) | D8: 주간2교대 | E8: =IF($D8="","",INDEX('1.기준정보'!$C$22:$H$28,MATCH($A8,'1.기준정보'!$A$22:$A$28,0),MATCH($D8,'1.기준정보'!$C$21:$H$21,0))) | F8: 주간2교대+잔업 | G8: =IF($F8="","",INDEX('1.기준정보'!$C$22:$H$28,MATCH($A8,'1.기준정보'!$A$22:$A$28,0),MATCH($F8,'1.기준정보'!$C$21:$H$21,0)))
A9: 5호기 | B9: 주간2교대 | C9: =IF($B9="","",INDEX('1.기준정보'!$C$22:$H$28,MATCH($A9,'1.기준정보'!$A$22:$A$28,0),MATCH($B9,'1.기준정보'!$C$21:$H$21,0))) | D9: 주간2교대 | E9: =IF($D9="","",INDEX('1.기준정보'!$C$22:$H$28,MATCH($A9,'1.기준정보'!$A$22:$A$28,0),MATCH($D9,'1.기준정보'!$C$21:$H$21,0))) | F9: 주간2교대+잔업 | G9: =IF($F9="","",INDEX('1.기준정보'!$C$22:$H$28,MATCH($A9,'1.기준정보'!$A$22:$A$28,0),MATCH($F9,'1.기준정보'!$C$21:$H$21,0)))
A10: 6호기 | B10: 1교대 | C10: =IF($B10="","",INDEX('1.기준정보'!$C$22:$H$28,MATCH($A10,'1.기준정보'!$A$22:$A$28,0),MATCH($B10,'1.기준정보'!$C$21:$H$21,0))) | D10: 1교대+잔업 | E10: =IF($D10="","",INDEX('1.기준정보'!$C$22:$H$28,MATCH($A10,'1.기준정보'!$A$22:$A$28,0),MATCH($D10,'1.기준정보'!$C$21:$H$21,0))) | F10: 주간2교대+잔업 | G10: =IF($F10="","",INDEX('1.기준정보'!$C$22:$H$28,MATCH($A10,'1.기준정보'!$A$22:$A$28,0),MATCH($F10,'1.기준정보'!$C$21:$H$21,0)))
A11: 7호기 | B11: 1교대 | C11: =IF($B11="","",INDEX('1.기준정보'!$C$22:$H$28,MATCH($A11,'1.기준정보'!$A$22:$A$28,0),MATCH($B11,'1.기준정보'!$C$21:$H$21,0))) | D11: 1교대+잔업 | E11: =IF($D11="","",INDEX('1.기준정보'!$C$22:$H$28,MATCH($A11,'1.기준정보'!$A$22:$A$28,0),MATCH($D11,'1.기준정보'!$C$21:$H$21,0))) | F11: 1교대+잔업 | G11: =IF($F11="","",INDEX('1.기준정보'!$C$22:$H$28,MATCH($A11,'1.기준정보'!$A$22:$A$28,0),MATCH($F11,'1.기준정보'!$C$21:$H$21,0)))
A12: 8호기 | B12: 미가동 | C12: =IF($B12="","",INDEX('1.기준정보'!$C$22:$H$28,MATCH($A12,'1.기준정보'!$A$22:$A$28,0),MATCH($B12,'1.기준정보'!$C$21:$H$21,0))) | D12: 1교대 | E12: =IF($D12="","",INDEX('1.기준정보'!$C$22:$H$28,MATCH($A12,'1.기준정보'!$A$22:$A$28,0),MATCH($D12,'1.기준정보'!$C$21:$H$21,0))) | F12: 1교대+잔업 | G12: =IF($F12="","",INDEX('1.기준정보'!$C$22:$H$28,MATCH($A12,'1.기준정보'!$A$22:$A$28,0),MATCH($F12,'1.기준정보'!$C$21:$H$21,0)))
A13: 일 합계(개) | C13: =SUM(C6:C12) | E13: =SUM(E6:E12) | G13: =SUM(G6:G12)
A15: ② 주간 환산 및 AP 목표 대비 판정
A16: 시나리오 | B16: 일 물량(개) | C16: 가동일수 | D16: 주간 물량(개) | E16: AP 목표(23만) 대비 | F16: AP 보수(20만) 대비 | G16: 판정
A17: A. 현행 (주간2교대 2대·잔업 최소) | B17: =C13 | C17: ='1.기준정보'!$B$6 | D17: =$B17*$C17 | E17: =IF('1.기준정보'!$B$7=0,0,$D17/'1.기준정보'!$B$7) | F17: =IF('1.기준정보'!$B$8=0,0,$D17/'1.기준정보'!$B$8) | G17: =IF($D17>='1.기준정보'!$B$7,"AP 목표 충족",IF($D17>='1.기준정보'!$B$8,"보수기준 충족 · 목표 미달","목표·보수기준 모두 미달"))
A18: B. 잔업 복원 | B18: =E13 | C18: ='1.기준정보'!$B$6 | D18: =$B18*$C18 | E18: =IF('1.기준정보'!$B$7=0,0,$D18/'1.기준정보'!$B$7) | F18: =IF('1.기준정보'!$B$8=0,0,$D18/'1.기준정보'!$B$8) | G18: =IF($D18>='1.기준정보'!$B$7,"AP 목표 충족",IF($D18>='1.기준정보'!$B$8,"보수기준 충족 · 목표 미달","목표·보수기준 모두 미달"))
A19: C. 풀가동 (2교대 3라인 + 잔업) | B19: =G13 | C19: ='1.기준정보'!$B$6 | D19: =$B19*$C19 | E19: =IF('1.기준정보'!$B$7=0,0,$D19/'1.기준정보'!$B$7) | F19: =IF('1.기준정보'!$B$8=0,0,$D19/'1.기준정보'!$B$8) | G19: =IF($D19>='1.기준정보'!$B$7,"AP 목표 충족",IF($D19>='1.기준정보'!$B$8,"보수기준 충족 · 목표 미달","목표·보수기준 모두 미달"))
A21: ③ 회신 시 반드시 명시할 전제조건 (조건 없는 Yes 금지)
A22: ⓐ 포장재·부자재 D-3 확정 입고 (미입고 시 해당 비가동은 원청 귀책 LOSS로 정산)
A23: ⓑ OP 인원 확보 — 주간2교대 3라인 편성 시 필요인원 대비 결원 해소 (충원 또는 다능공 전환 소요기간 명시)
A24: ⓒ 주간계획 확정 시점 준수 — 계획 변경 시 도급 일계획 재수립 리드타임 필요
A25: ⓓ 근무편성(교대·잔업) 결정 주체는 제니엘 관리 라인 — AP는 필요 물량만 제시 (도급 적법성 유지)
