Workbook

Sheet 00_표지
B2: BY27 연간 운영계획
B4: 제니엘 AP 대전공장 센터 · 생산도급/업무도급 4축
B5: 대상기간 2027.01 ~ 2027.12
B8: 문서 목적 | C8: 센터장(현장소장) 연간 업무계획 — 목표·일정·자원·리스크를 한 문서에서 관리하고 월 단위로 실적을 채워 본사 보고에 그대로 사용한다.
B9: 적용 범위 | C9: 아모레퍼시픽 생산도급/업무도급 + 코스비전 생산도급/업무도급 (4축, 총 354명). 집계는 고객×계약유형 분리가 기본이며 합산 시 출처를 명시한다.
B10: 운영 축 | C10: P1 생산성·LOSS · P2 인력·조직 · P3 품질·안전·노무 · P4 원가·정산·단가 · P5 표준화·디지털
B11: 중점과제 | C11: 15건 (축별 3건)
B12: KPI | C12: 12개 — 매월 실적 입력 시 달성률 자동 산출
B13: 사용법 | C13: 노란 채움 + 파란 글씨 = 입력 셀. 검정 = 수식(수정 금지). 초록 = 다른 시트 참조. 01_기준전제의 입력값만 갱신하면 02·04 시트가 자동 재계산된다.
B14: 수치 신뢰도 | C14: 임률 35,121원/M·H · 원청귀책 52% · BY26 단가인상률(생산 +4.12% / 업무 +4.82%) · 4축 인원은 실적값. 그 외 BY26 기준값은 플레이스홀더이며 실적 입력이 필요하다 — 01_기준전제 '출처·근거' 열 참조.
B16: 시트 구성 | C16: 01_기준전제(입력) → 02_KPI목표 → 03_연간스케줄 → 04_중점과제 → 05_LOSS효율시뮬 → 06_인력계획 → 07_리스크등록부 → 08_운영루틴

Sheet 01_기준전제
A1: 01. 계획 기준·전제 (입력 시트)
A2: 노란 채움 + 파란 글씨 셀만 수정한다. 이 값이 02·05 시트로 전파된다.
A3: [1] 계약 4축 — 고객 × 계약유형
A4: 고객 | B4: 계약유형 | C4: 인원(명) | D4: 임률(원/M·H) | E4: 월 총공수(M·H) | F4: 월 도급비(원) | G4: 출처·근거
A5: 아모레퍼시픽 | B5: 생산도급 | C5: 153 | D5: 35121 | E5: =C5*$B$13 -> 26622 | F5: =E5*D5 -> 934991262 | G5: 사용자 제공 · BY26 실적 임률
A6: 아모레퍼시픽 | B6: 업무도급 | C6: 91 | D6: 35121 | E6: =C6*$B$13 -> 15834 | F6: =E6*D6 -> 556105914 | G6: AP 임률 준용(가정) · BY27 계약 임률 입력 필요
A7: 코스비전 | B7: 생산도급 | C7: 55 | E7: =C7*$B$13 -> 9570 | F7: =E7*D7 -> 0 | G7: 별도 임률 · 입력 필요
A8: 코스비전 | B8: 업무도급 | C8: 55 | E8: =C8*$B$13 -> 9570 | F8: =E8*D8 -> 0 | G8: 별도 임률 · 입력 필요
A9: 합계 | C9: =SUM(C5:C8) -> 354 | D9: — | E9: =SUM(E5:E8) -> 61596 | F9: =SUM(F5:F8) -> 1491097176 | G9: 임률이 다른 계약을 합산한 값 — 단가 비교에는 사용하지 말 것
A11: [2] 운영 기준값·가정
A12: 항목 | B12: 값 | C12: 단위 | G12: 출처·근거
A13: 월 기준공수(1인) | B13: 174 | C13: M·H | G13: 가정 · 주40H×4.35주 기준. 실적 반영 시 수정
A14: 연 가동월수 | B14: 12 | C14: 개월 | G14: 가정
A15: BY26 LOSS율 | B15: 0.06 | C15: % | G15: 가정(플레이스홀더) · BY26 MES 실적 입력 필요
A16: BY26 원청귀책 LOSS 비중 | B16: 0.52 | C16: % | G16: 사용자 제공 · BY26 MES 8개월 귀속분석 실적
A17: BY26 실효율 | B17: 0.88 | C17: % | G17: 가정(플레이스홀더) · 라인 실적 입력 필요
A18: BY27 목표효율 | B18: 0.9 | C18: % | G18: 목표값 · 라인별 재설정 후 확정(과제 A-03)
A19: BY26 월평균 결원율 | B19: 0.038 | C19: % | G19: 가정(플레이스홀더) · 실적 입력 필요
A20: BY26 월평균 이직률 | B20: 0.042 | C20: % | G20: 가정(플레이스홀더) · 실적 입력 필요
A21: BY26 다능공 보유율 | B21: 0.45 | C21: % | G21: 가정(플레이스홀더) · 스킬매트릭스 집계 필요
A22: BY26 산재 건수 | B22: 3 | C22: 건 | G22: 가정(플레이스홀더) · 실적 입력 필요
A23: BY26 도급귀책 품질클레임 | B23: 10 | C23: 건 | G23: 가정(플레이스홀더) · 실적 입력 필요
A24: BY26 월마감 리드타임 | B24: 5 | C24: 일 | G24: 가정(플레이스홀더) · 실적 입력 필요
... A27: 도급귀책 LOSS 저감 목표율 | B27: 0.15 | C27: % | G27: 목표값 · 과제 A-02
A30: 범례 | B30: 입력 셀 | C30: 수식 | D30: 타 시트 참조 | G30: 빨간 '출처·근거' = 플레이스홀더(가정). BY26 실적을 확보하는 즉시 교체할 것.

Sheet 02_KPI목표
A1: 02. BY27 KPI 목표 · 월별 실적
A2: 기준값은 01_기준전제에서 자동 참조. 월별 실적을 입력하면 연평균·달성률이 산출된다.
A4: ID | B4: 축 | C4: KPI | D4: 산식 | E4: BY26 기준 | F4: BY27 목표 | G4: 목표 설정근거 | H4: 1월 | I4: 2월 | J4: 3월 | K4: 4월 | L4: 5월 | M4: 6월 | N4: 7월 | O4: 8월 | P4: 9월 | Q4: 10월 | R4: 11월 | S4: 12월 | T4: 연평균/계 | U4: 달성률
A5: K01 | B5: P1 | C5: LOSS율 | D5: LOSS 공수 ÷ 총 투입공수 | E5: =01_기준전제!B15 -> 0.06 | F5: =E5*0.85 -> 0.051 | G5: 기준 × 0.85 | T5: =IFERROR(AVERAGE(H5:S5),"") | U5: =IFERROR(IF(T5="","",F5/T5),"")
A6: K02 | B6: P1 | C6: 도급귀책 LOSS 공수 | D6: LOSS 공수 × 도급귀책 비중 | E6: =05_LOSS효율시뮬!J9 -> 1773.9648 | F6: =E6*0.85 -> 1507.8701 | G6: 기준 × 0.85 | T6: =IFERROR(AVERAGE(H6:S6),"") | U6: =IFERROR(IF(T6="","",F6/T6),"")
A7: K03 | B7: P1 | C7: 원청귀책 LOSS 비중 | D7: 원청귀책 LOSS ÷ 전체 LOSS | E7: =01_기준전제!B16 -> 0.52 | F7: 0.52 | G7: 근거 유지·확대 | T7: =IFERROR(AVERAGE(H7:S7),"") | U7: =IFERROR(IF(T7="","",T7/F7),"")
A8: K04 | B8: P1 | C8: 실효율 | D8: 실적공수 ÷ 표준공수 | E8: =01_기준전제!B17 -> 0.88 | F8: =E8+0.02 -> 0.9 | G8: 기준 + 2.0%p | T8: =IFERROR(AVERAGE(H8:S8),"") | U8: =IFERROR(IF(T8="","",T8/F8),"")
A9: K05 | B9: P2 | C9: 월평균 결원율 | D9: 결원 ÷ 정원 | E9: =01_기준전제!B19 -> 0.038 | F9: 0.03 | G9: 3.0% 이하 | T9: =IFERROR(AVERAGE(H9:S9),"") | U9: =IFERROR(IF(T9="","",F9/T9),"")
A10: K06 | B10: P2 | C10: 월평균 이직률 | D10: 퇴사 ÷ 평균 재직 | E10: =01_기준전제!B20 -> 0.042 | F10: 0.035 | G10: 3.5% 이하 | T10: =IFERROR(AVERAGE(H10:S10),"") | U10: =IFERROR(IF(T10="","",F10/T10),"")
A11: K07 | B11: P2 | C11: 다능공 보유율 | D11: 2공정 이상 가능 인원 ÷ 총원 | E11: =01_기준전제!B21 -> 0.45 | F11: 0.6 | G11: 60% 이상 | T11: =IFERROR(AVERAGE(H11:S11),"") | U11: =IFERROR(IF(T11="","",T11/F11),"")
A12: K08 | B12: P3 | C12: 중대재해 | D12: 발생 건수 | E12: — | F12: 0 | G12: 0건 | T12: =IF(COUNT(H12:S12)=0,"",SUM(H12:S12)) | U12: =IF(T12="","",IF(T12=0,1,0))
A13: K09 | B13: P3 | C13: 산재 건수 | D13: 발생 건수 | E13: =01_기준전제!B22 -> 3 | F13: =E13*0.7 -> 2.1 | G13: 기준 × 0.70 | T13: =IF(COUNT(H13:S13)=0,"",SUM(H13:S13)) | U13: =IFERROR(IF(T13="","",F13/T13),"")
A14: K10 | B14: P3 | C14: 도급귀책 품질클레임 | D14: 도급귀책 판정 건수 | E14: =01_기준전제!B23 -> 10 | F14: =E14*0.7 -> 7 | G14: 기준 × 0.70 | T14: =IF(COUNT(H14:S14)=0,"",SUM(H14:S14)) | U14: =IFERROR(IF(T14="","",F14/T14),"")
A15: K11 | B15: P4 | C15: 월마감 리드타임 | D15: 마감 완료일 − 월말 | E15: =01_기준전제!B24 -> 5 | F15: 3 | G15: 3일 이내 | T15: =IFERROR(AVERAGE(H15:S15),"") | U15: =IFERROR(IF(T15="","",F15/T15),"")
A16: K12 | B16: P5 | C16: 주간계획 업로드 준수율 | D16: 업로드 주차 ÷ 전체 주차 | E16: — | F16: 0.95 | G16: 95% 이상 | T16: =IFERROR(AVERAGE(H16:S16),"") | U16: =IFERROR(IF(T16="","",T16/F16),"")
A18: 주 | C18: 달성률: 낮을수록 좋은 KPI(LOSS율·결원율·이직률·산재·클레임·마감일)는 목표÷실적, 높을수록 좋은 KPI는 실적÷목표. 100% 이상이면 목표 달성. 중대재해는 0건일 때만 100%.

Sheet 03_연간스케줄
A1: 03. BY27 연간 마스터 스케줄
A2: 월 × 운영축 기준 핵심 업무. 분기 마감·법정 일정·협상 일정을 축으로 배치했다.
A4: 월 | B4: 축 | C4: 운영축 | D4: 핵심 업무 | E4: 분기 | F4: 고정 일정
A5: 1월 | B5: P1 | C5: 생산성·LOSS | D5: BY27 LOSS 사유코드·귀책룰 확정, 시스템 반영 | E5: Q1 | F5: 안전보건계획
B6: P2 | C6: 인력·조직 | D6: 조직·R&R 확정, 연간 교육계획 수립
B7: P3 | C7: 품질·안전·노무 | D7: 연간 안전보건계획 수립·게시, 위험성평가 연간계획
B8: P4 | C8: 원가·정산·단가 | D8: BY27 단가 적용 개시, 청구기준 재확인
B9: P5 | C9: 표준화·디지털 | D9: 월간 경영보고 템플릿 v27 배포
A10: 2월 | B10: P1 | C10: 생산성·LOSS | D10: 1월 LOSS 귀속리포트 최초 발행 | E10: Q1 | F10: 설 연휴
B11: P2 | C11: 인력·조직 | D11: 설 연휴 인력운영, 스킬매트릭스 기준 확정
B12: P3 | C12: 품질·안전·노무 | D12: 1분기 정기 안전보건교육(법정)
B13: P4 | C13: 원가·정산·단가 | D13: 1월 마감 정산 검증(고객×계약유형 4축)
B14: P5 | C14: 표준화·디지털 | D14: 주간계획 업로드 프로세스 현장 정착
A15: 3월 | B15: P1 | C15: 생산성·LOSS | D15: 도급귀책 3대 항목 개선 착수 | E15: Q1 | F15: 1Q 경영보고
B16: P2 | C16: 인력·조직 | D16: 1Q 결원·이직 리뷰, 채용 리드타임 개선
B17: P3 | C17: 품질·안전·노무 | D17: 위험성평가(정기) 실시
B18: P4 | C18: 원가·정산·단가 | D18: 1Q 마감 · 본사 경영보고
B19: P5 | C19: 표준화·디지털 | D19: 조치추적 운영지표화
A20: 4월 | B20: P1 | C20: 생산성·LOSS | D20: 라인별 목표효율 재설정 | E20: Q2 | F20: 하절기 준비
B21: P2 | C21: 인력·조직 | D21: 다능공 교육 1차
B22: P3 | C22: 품질·안전·노무 | D22: 하절기 대응계획 수립(HeatWatch 세팅·물품)
B23: P4 | C23: 원가·정산·단가 | D23: 1Q 손익 리뷰, 세탁실 별도정산 점검
B24: P5 | C24: 표준화·디지털 | D24: 본사 보고 자동화 1차 적용
A25: 5월 | B25: P1 | C25: 생산성·LOSS | D25: 효율 편차 주간관리 정착 | E25: Q2 | F25: 자체진단 1차
B26: P2 | C26: 인력·조직 | D26: 조장·반장 리더십 교육 1차
B27: P3 | C27: 품질·안전·노무 | D27: 불법파견 자체진단 1차(상반기)
B28: P4 | C28: 원가·정산·단가 | D28: 4월 마감, 물량변동 대응 인력계획
B29: P5 | C29: 표준화·디지털 | D29: 플랫폼 사용률 점검·보완
A30: 6월 | B30: P1 | C30: 생산성·LOSS | D30: 상반기 LOSS 실적 집계·검증 | E30: Q2 | F30: 상반기 마감
B31: P2 | C31: 인력·조직 | D31: 하계휴가 인력운영 계획 확정
B32: P3 | C32: 품질·안전·노무 | D32: HeatWatch 가동, 2Q 안전보건교육
B33: P4 | C33: 원가·정산·단가 | D33: 상반기 마감 · 2Q 경영보고
B34: P5 | C34: 표준화·디지털 | D34: 상반기 운영 리뷰
A35: 7월 | B35: P1 | C35: 생산성·LOSS | D35: 하한기 CAPA 대응 LOSS 관리 | E35: Q3 | F35: 하계휴가
B36: P2 | C36: 인력·조직 | D36: 하계휴가 운영, 대체인력 배치
B37: P3 | C37: 품질·안전·노무 | D37: 온열질환 예방 집중관리
B38: P4 | C38: 원가·정산·단가 | D38: 6월 마감, 상반기 손익 분석
B39: P5 | C39: 표준화·디지털 | D39: 데이터 정합성 감사
A40: 8월 | B40: P1 | C40: 생산성·LOSS | D40: 폭염 LOSS 귀책 구분기록 강화 | E40: Q3 | F40: 협상 D-3M
B41: P2 | C41: 인력·조직 | D41: 하반기 채용·결원 보충
...

Sheet 04_중점과제
A1: 04. BY27 중점과제 15건 · 실행 간트
A2: 난이도 High 과제는 월별 진척을 별도 관리한다. 진척률은 입력 셀.
A4: ID | B4: 축 | C4: 과제명 | D4: 정량 목표 | E4: 핵심 산출물 | F4: 난이도 | G4: 담당 | H4: 기간 | I4: 1 | J4: 2 | K4: 3 | L4: 4 | M4: 5 | N4: 6 | O4: 7 | P4: 8 | Q4: 9 | R4: 10 | S4: 11 | T4: 12 | U4: 진척률
A5: A-01 | B5: P1 | C5: LOSS 사유코드·귀책룰 BY27 확정 | D5: 귀책 미분류 LOSS 비중 ≤3% | E5: LOSS 카테고리 정의서 v3 · 월 귀속리포트 | F5: Mid | G5: 센터장/생산관리 | H5: 1~3월
A6: A-02 | B6: P1 | C6: 도급귀책 LOSS 3대 항목 저감 | D6: 도급귀책 LOSS 공수 전년比 -15% | E6: 3대 항목(휴식 미복귀·교대준비·초기불량) 개선안 | F6: Mid | G6: 생산반장 | H6: 2~12월
A7: A-03 | B7: P1 | C7: 라인별 목표효율 재설정·편차관리 | D7: 효율 GAP ≤2%p 라인 비중 80%↑ | E7: 라인별 표준효율표 · 주간 편차관리 시트 | F7: High | G7: 센터장/생산관리 | H7: 4~12월
A8: B-01 | B8: P2 | C8: 결원·조기이탈 안정화 | D8: 월평균 결원율 ≤3.0% · 이직률 ≤3.5% | E8: 채용 파이프라인 · 입사 4주 온보딩 체크리스트 | F8: High | G8: 인사담당 | H8: 1~12월
A9: B-02 | B9: P2 | C9: 다능공 스킬매트릭스 운영 | D9: 다능공(2공정↑) 보유율 60% | E9: 공정별 스킬매트릭스 · 연 2회 교육 | F9: Mid | G9: 교육담당 | H9: 1~9월
A10: B-03 | B10: P2 | C10: 조장·반장 관리라인 역량 | D10: 리더 교육 이수율 100% · 관할인원 표준화 | E10: 지휘체계 R&R 정의서 · 월 리더미팅 | F10: Mid | G10: 센터장 | H10: 1~12월
A11: C-01 | B11: P3 | C11: 중대재해 Zero·산재 저감 | D11: 중대재해 0건 · 산재 전년比 -30% | E11: 연간 안전보건계획 · 위험성평가 · 아차사고 대장 | F11: Mid | G11: 안전담당 | H11: 1~12월
A12: C-02 | B12: P3 | C12: 하절기 온열질환 대응(HeatWatch) | D12: 온열질환 0건 · 폭염 LOSS 전년比 -20% | E12: 체감온도 휴식 프로토콜 · HeatWatch 운영 | F12: Low | G12: 안전담당 | H12: 4~9월
A13: C-03 | B13: P3 | C13: 불법파견(위장도급) 자체진단 | D13: 고위험 항목 0건 · 반기 2회 진단 | E13: 진단 130항목 체크리스트 · 지시경로 기록 | F13: High | G13: 센터장 | H13: 5월·10월
A14: C-04 | B14: P3 | C14: 도급귀책 품질클레임 저감 | D14: 도급귀책 클레임 전년比 -30% | E14: 초·중·종물 검사 준수율 · OPL 전개 | F14: Mid | G14: 품질담당 | H14: 2~12월
A15: D-01 | B15: P4 | C15: 월마감 4축 분리집계 표준화 | D15: 정산 오류 0건 · 마감 D+3 | E15: 마감 체크리스트 · 고객×계약유형 집계 양식 | F15: Mid | G15: 정산담당 | H15: 1~4월
A16: D-02 | B16: P4 | C16: BY28 단가협상 근거 축적 | D16: 10월까지 협상 데이터패키지 완성 | E16: LOSS 귀속 확정치 · 단가 산출내역서 | F16: High | G16: 센터장 | H16: 8~11월
... A19: E-02 | B19: P5 | C19: 본사 월간보고 표준화 | D19: 보고 작성공수 -50% | E19: 월간 경영보고 템플릿 v27(4축 분리) | F19: Low | G19: 센터장 | H19: 1~3월
C20: 전체 진척률(단순평균) | U20: =IFERROR(AVERAGE(U5:U19),0) -> 0
A22: 난이도 기준 | C22: Low = 기존 자원으로 즉시 실행 / Mid = 타 부서·원청 협의 필요 / High = 원청 합의 또는 본사 승인 필요, 실패 시 손익 직결

Sheet 05_LOSS효율시뮬
A1: 05. LOSS 비용 · 효율 GAP 시뮬레이션
A2: 01_기준전제 입력값에 연동. LOSS율·귀책비중·효율은 전 계약 공통 가정 — 축별 실적 확보 시 행별로 분리 입력할 것.
A3: [1] LOSS 비용 — 계약 4축
A4: 구분 | B4: 인원 | C4: 월 기준공수 | D4: 월 총공수 | E4: 임률 | F4: 월 도급비 | G4: LOSS율 | H4: 월 LOSS공수 | I4: 원청귀책H | J4: 도급귀책H | K4: 도급귀책 비용/월 | L4: 저감목표 | M4: 월 절감액 | N4: 연 절감액
A5: 아모레퍼시픽 생산도급 | B5: =01_기준전제!C5 -> 153 | C5: =01_기준전제!$B$13 -> 174 | D5: =B5*C5 -> 26622 | E5: =01_기준전제!D5 -> 35121 | F5: =D5*E5 -> 934991262 | G5: =01_기준전제!$B$15 -> 0.06 | H5: =D5*G5 -> 1597.32 | I5: =H5*01_기준전제!$B$16 -> 830.6064 | J5: =H5-I5 -> 766.7136 | K5: =J5*E5 -> 26927748 | L5: =01_기준전제!$B$27 -> 0.15 | M5: =K5*L5 -> 4039162.3 | N5: =M5*01_기준전제!$B$14 -> 48469947
A6: 아모레퍼시픽 업무도급 | B6: =01_기준전제!C6 -> 91 | C6: =01_기준전제!$B$13 -> 174 | D6: =B6*C6 -> 15834 | E6: =01_기준전제!D6 -> 35121 | F6: =D6*E6 -> 556105914 | G6: =01_기준전제!$B$15 -> 0.06 | H6: =D6*G6 -> 950.04 | I6: =H6*01_기준전제!$B$16 -> 494.0208 | J6: =H6-I6 -> 456.0192 | K6: =J6*E6 -> 16015850 | L6: =01_기준전제!$B$27 -> 0.15 | M6: =K6*L6 -> 2402377.5 | N6: =M6*01_기준전제!$B$14 -> 28828531
A7: 코스비전 생산도급 | B7: =01_기준전제!C7 -> 55 | C7: =01_기준전제!$B$13 -> 174 | D7: =B7*C7 -> 9570 | E7: =01_기준전제!D7 -> 0 | F7: =D7*E7 -> 0 | G7: =01_기준전제!$B$15 -> 0.06 | H7: =D7*G7 -> 574.2 | I7: =H7*01_기준전제!$B$16 -> 298.584 | J7: =H7-I7 -> 275.616 | K7: =J7*E7 -> 0 | L7: =01_기준전제!$B$27 -> 0.15 | M7: =K7*L7 -> 0 | N7: =M7*01_기준전제!$B$14 -> 0
A8: 코스비전 업무도급 | B8: =01_기준전제!C8 -> 55 | C8: =01_기준전제!$B$13 -> 174 | D8: =B8*C8 -> 9570 | E8: =01_기준전제!D8 -> 0 | F8: =D8*E8 -> 0 | G8: =01_기준전제!$B$15 -> 0.06 | H8: =D8*G8 -> 574.2 | I8: =H8*01_기준전제!$B$16 -> 298.584 | J8: =H8-I8 -> 275.616 | K8: =J8*E8 -> 0 | L8: =01_기준전제!$B$27 -> 0.15 | M8: =K8*L8 -> 0 | N8: =M8*01_기준전제!$B$14 -> 0
A9: 합계 | B9: =SUM(B5:B8) -> 354 | C9: — | D9: =SUM(D5:D8) -> 61596 | E9: — | F9: =SUM(F5:F8) -> 1491097176 | G9: — | H9: =SUM(H5:H8) -> 3695.76 | I9: =SUM(I5:I8) -> 1921.7952 | J9: =SUM(J5:J8) -> 1773.9648 | K9: =SUM(K5:K8) -> 42943599 | L9: — | M9: =SUM(M5:M8) -> 6441539.8 | N9: =SUM(N5:N8) -> 77298478
A10: 주 | B10: 코스비전 임률 미입력 시 해당 행은 0으로 계산된다. 임률이 서로 다른 계약의 합계액은 대외 제시용으로 쓰지 말 것.
A12: [2] 효율 GAP 환산 — KPI 미달 비용(추정)
A13: 구분 | B13: 월 총공수 | C13: 목표효율 | D13: 실효율 | E13: GAP(%p) | F13: 월 GAP 공수 | G13: 임률 | H13: 월 환산액 | I13: 연 환산액
A14: 아모레퍼시픽 생산도급 | B14: =D5 -> 26622 | C14: =01_기준전제!$B$18 -> 0.9 | D14: =01_기준전제!$B$17 -> 0.88 | E14: =C14-D14 -> 0.02 | F14: =B14*E14 -> 532.44 | G14: =E5 -> 35121 | H14: =F14*G14 -> 18699825 | I14: =H14*01_기준전제!$B$14 -> 2.243979e+08
A15: 아모레퍼시픽 업무도급 | B15: =D6 -> 15834 | C15: =01_기준전제!$B$18 -> 0.9 | D15: =01_기준전제!$B$17 -> 0.88 | E15: =C15-D15 -> 0.02 | F15: =B15*E15 -> 316.68 | G15: =E6 -> 35121 | H15: =F15*G15 -> 11122118 | I15: =H15*01_기준전제!$B$14 -> 1.3346542e+08
A16: 코스비전 생산도급 | B16: =D7 -> 9570 | C16: =01_기준전제!$B$18 -> 0.9 | D16: =01_기준전제!$B$17 -> 0.88 | E16: =C16-D16 -> 0.02 | F16: =B16*E16 -> 191.4 | G16: =E7 -> 0 | H16: =F16*G16 -> 0 | I16: =H16*01_기준전제!$B$14 -> 0
A17: 코스비전 업무도급 | B17: =D8 -> 9570 | C17: =01_기준전제!$B$18 -> 0.9 | D17: =01_기준전제!$B$17 -> 0.88 | E17: =C17-D17 -> 0.02 | F17: =B17*E17 -> 191.4 | G17: =E8 -> 0 | H17: =F17*G17 -> 0 | I17: =H17*01_기준전제!$B$14 -> 0
A18: 합계 | B18: =SUM(B14:B17) -> 61596 | C18: — | D18: — | E18: — | F18: =SUM(F14:F17) -> 1231.92 | G18: — | H18: =SUM(H14:H17) -> 29821944 | I18: =SUM(I14:I17) -> 3.5786332e+08
A19: 주 | B19: [1] LOSS 비용은 실제 비조업 공수 기준 — 정산·협상 근거. [2] 효율 GAP은 KPI 미달의 기회비용 추정치. 두 값은 성격이 달라 합산하지 않는다.
A21: [3] 도급귀책 LOSS 저감 시나리오 — 연간 절감액
A22: 시나리오 | B22: 저감률 | C22: 연 절감액(원) | D22: 비고
A23: 보수 | B23: 0.1 | C23: =$K$9*B23*01_기준전제!$B$14 -> 51532318 | D23: 3대 항목 중 1개만 정착
A24: 기준 | B24: 0.15 | C24: =$K$9*B24*01_기준전제!$B$14 -> 77298478 | D24: BY27 목표 — 과제 A-02
A25: 도전 | B25: 0.2 | C25: =$K$9*B25*01_기준전제!$B$14 -> 1.0306464e+08 | D25: 라인 효율관리(A-03) 동반 성공 시

Sheet 06_인력계획
A1: 06. BY27 인력 운영계획
A2: 정원 대비 월별 재직/결원/신규/퇴사를 입력하면 결원율·이직률이 산출된다.
A3: [1] 정원 · 계약 4축
A4: 구분 | B4: 정원(명) | C4: 구성비 | D4: 비고
A5: 아모레퍼시픽 생산도급 | B5: =01_기준전제!C5 -> 153 | C5: =IFERROR(B5/$B$9,0) -> 0.43220339
A6: 아모레퍼시픽 업무도급 | B6: =01_기준전제!C6 -> 91 | C6: =IFERROR(B6/$B$9,0) -> 0.25706215
A7: 코스비전 생산도급 | B7: =01_기준전제!C7 -> 55 | C7: =IFERROR(B7/$B$9,0) -> 0.15536723
A8: 코스비전 업무도급 | B8: =01_기준전제!C8 -> 55 | C8: =IFERROR(B8/$B$9,0) -> 0.15536723 | D8: 세탁실 별도정산 포함
A9: 합계 | B9: =SUM(B5:B8) -> 354 | C9: =IFERROR(B9/B9,0) -> 1
A11: [2] 월별 인력 실적 (입력)
A12: 항목 | B12: BY27 목표 | C12: 단위 | D12: 산식 | E12: 1월 | F12: 2월 | G12: 3월 | H12: 4월 | I12: 5월 | J12: 6월 | K12: 7월 | L12: 8월 | M12: 9월 | N12: 10월 | O12: 11월 | P12: 12월 | Q12: 연평균
A13: 평균 재직인원 | B13: — | C13: 명 | D13: 월평균 실 재직 | Q13: =IFERROR(AVERAGE(E13:P13),"")
A14: 결원 인원 | B14: — | C14: 명 | D14: 정원 − 재직 | Q14: =IFERROR(AVERAGE(E14:P14),"")
A15: 신규 입사 | B15: — | C15: 명 | D15: 월 입사자 | Q15: =IFERROR(SUM(E15:P15),"") -> 0
A16: 퇴사 | B16: — | C16: 명 | D16: 월 퇴사자 | Q16: =IFERROR(SUM(E16:P16),"") -> 0
A17: 4주 내 조기이탈 | B17: — | C17: 명 | D17: 입사 4주 이내 퇴사 | Q17: =IFERROR(SUM(E17:P17),"") -> 0
A18: 결원율 | B18: =02_KPI목표!F9 -> 0.03 | C18: % | D18: 결원 ÷ 정원 | E18: =IFERROR(E14/$B$9,"") -> 0 | F18: =IFERROR(F14/$B$9,"") -> 0 | G18: =IFERROR(G14/$B$9,"") -> 0 | H18: =IFERROR(H14/$B$9,"") -> 0 | I18: =IFERROR(I14/$B$9,"") -> 0 | J18: =IFERROR(J14/$B$9,"") -> 0 | K18: =IFERROR(K14/$B$9,"") -> 0 | L18: =IFERROR(L14/$B$9,"") -> 0 | ... P18: =IFERROR(P14/$B$9,"") -> 0 | Q18: =IFERROR(AVERAGE(E18:P18),"") -> 0
A19: 이직률 | B19: =02_KPI목표!F10 -> 0.035 | C19: % | D19: 퇴사 ÷ 평균 재직 | E19: =IFERROR(E16/E13,"") | F19: =IFERROR(F16/F13,"") | G19: =IFERROR(G16/G13,"") | H19: =IFERROR(H16/H13,"") | I19: =IFERROR(I16/I13,"") | J19: =IFERROR(J16/J13,"") | K19: =IFERROR(K16/K13,"") | L19: =IFERROR(L16/L13,"") | ... P19: =IFERROR(P16/P13,"") | Q19: =IFERROR(AVERAGE(E19:P19),"")
A20: 조기이탈 비중 | B20: — | C20: % | D20: 4주 내 이탈 ÷ 신규 입사 | E20: =IFERROR(E17/E15,"") | F20: =IFERROR(F17/F15,"") | G20: =IFERROR(G17/G15,"") | H20: =IFERROR(H17/H15,"") | I20: =IFERROR(I17/I15,"") | J20: =IFERROR(J17/J15,"") | K20: =IFERROR(K17/K15,"") | L20: =IFERROR(L17/L15,"") | ... P20: =IFERROR(P17/P15,"") | Q20: =IFERROR(AVERAGE(E20:P20),"")
A22: 주 | B22: 결원 1명당 월 손실 = 월 기준공수 × 임률. 결원율 1%p 상승은 AP 생산도급 기준 월 약 940만원 수준의 공수 부족을 뜻한다(153명×174H×35,121원×1%). 대체 잔업으로 메우면 비용은 더 커진다.

Sheet 07_리스크등록부
A1: 07. BY27 리스크 등록부
A2: 영향×발생가능성으로 우선순위를 정하고, 점검주기에 맞춰 상태를 갱신한다.
A4: ID | B4: 구분 | C4: 리스크 | D4: 영향 | E4: 발생가능성 | F4: 대응 방안 | G4: 담당 | H4: 점검주기 | I4: 상태
A5: R1 | B5: 노무 | C5: 불법파견(위장도급) 판정 — 현장 직접 지시·근태 직접관리 적발 | D5: 高 | E5: 中 | F5: 지시는 도급사 관리라인 경유 표준화 · 반기 자체진단 130항목 · 지시기록 보존 | G5: 센터장 | H5: 반기 | I5: 미착수
A6: R2 | B6: 안전 | C6: 중대재해 발생 — 중대재해처벌법 수사·가동 중단 | D6: 高 | E6: 低 | F6: 연간 안전보건계획 · 위험성평가(정기/수시) · 아차사고 신고제 | G6: 안전담당 | H6: 월 | I6: 미착수
A7: R3 | B7: 품질 | C7: 도급귀책 클레임 증가 — BY28 단가협상 불리 | D7: 中 | E7: 中 | F7: 초·중·종물 검사 준수율 관리 · OPL 즉시 전개 | G7: 품질담당 | H7: 월 | I7: 미착수
A8: R4 | B8: 인력 | C8: 결원율 상승 — 잔업·대체 비용 증가, 효율 저하 | D8: 中 | E8: 高 | F8: 채용 파이프라인 상시화 · 입사 4주 온보딩 · 다능공 확대 | G8: 인사담당 | H8: 주 | I8: 미착수
A9: R5 | B9: 계약 | C9: BY28 단가 인상 미달 — 손익 악화 | D9: 高 | E9: 中 | F9: LOSS 귀속 근거 축적(1~10월) · 산출내역서 정교화 | G9: 센터장 | H9: 분기 | I9: 미착수
A10: R6 | B10: 안전 | C10: 하절기 온열질환 — 가동률 저하·산재 | D10: 中 | E10: 中 | F10: HeatWatch 체감온도 기준 휴식 프로토콜 · 냉방물품 사전확보 | G10: 안전담당 | H10: 일(하절기) | I10: 미착수
A11: R7 | B11: 정산 | C11: 4축 분리집계 오류 — 청구 누락/과청구 | D11: 中 | E11: 中 | F11: 마감 체크리스트 · 이중 검증 · 세탁실 별도정산 증빙 표준 | G11: 정산담당 | H11: 월 | I11: 미착수
A12: R8 | B12: 데이터 | C12: 플랫폼 미사용 — 계획 근거 데이터 소실 | D12: 中 | E12: 中 | F12: 주간 업로드 준수율 KPI화 · 미업로드 주차 소명 | G12: 센터장 | H12: 주 | I12: 미착수
A15: 최우선 | C15: R1(불법파견)·R5(BY28 단가) — 발생 시 계약·손익에 직접 타격. 나머지 과제보다 우선 자원 배분.

Sheet 08_운영루틴
A1: 08. 센터장 정기 운영 루틴
A2: 연간계획이 굴러가게 하는 반복 업무. 주기별로 고정한다.
A4: 주기 | B4: 업무
A5: 일간 | B5: 조회(관리라인 경유) · 전일 LOSS/결원 확인 · 현장 안전순회 · 이슈 에스컬레이션
A6: 주간 | B6: 월: 주간생산계획 업로드·배포 / 수: 조장회의 / 금: 주간 실적·효율 리뷰 및 차주 인력배치
A7: 월간 | B7: 월마감 정산(D+3) · 본사 월간 경영보고 · 안전보건협의체 · 교육 이수 점검 · 지연오더 취합
A8: 분기 | B8: 분기 경영보고 · 법정 안전보건교육 · 위험성평가 · KPI 목표 대비 실적 리뷰
A9: 반기 | B9: 불법파견 자체진단 · 인사평가 · 인력계획 재수립
A10: 연간 | B10: 안전보건계획 수립 · 단가협상(BY28) · 차년도 운영계획 확정 · 결산보고
A12: 지휘 원칙 | B12: 현장 작업자에 대한 지시는 반드시 도급사 관리라인(조장·반장)을 경유한다. 직접 지휘·근태 직접관리는 불법파견(위장도급) 판정 근거가 된다 — 리스크 R1.
